{
 "cells": [
  {
   "cell_type": "markdown",
   "metadata": {},
   "source": [
    "Train model to Segment Handwriting"
   ]
  },
  {
   "cell_type": "code",
   "execution_count": null,
   "metadata": {},
   "outputs": [
    {
     "name": "stderr",
     "output_type": "stream",
     "text": [
      "ERROR:root:Internal Python error in the inspect module.\n",
      "Below is the traceback from this internal error.\n",
      "\n",
      "ERROR:root:Internal Python error in the inspect module.\n",
      "Below is the traceback from this internal error.\n",
      "\n",
      "ERROR:root:Internal Python error in the inspect module.\n",
      "Below is the traceback from this internal error.\n",
      "\n"
     ]
    },
    {
     "name": "stdout",
     "output_type": "stream",
     "text": [
      "Traceback (most recent call last):\n",
      "  File \"c:\\users\\mcsch\\anaconda3\\envs\\tf20\\lib\\site-packages\\IPython\\core\\interactiveshell.py\", line 3343, in run_code\n",
      "    exec(code_obj, self.user_global_ns, self.user_ns)\n",
      "  File \"<ipython-input-1-f8a46eff5ac0>\", line 3, in <module>\n",
      "    from tensorflow_examples.models.pix2pix import pix2pix\n",
      "ModuleNotFoundError: No module named 'tensorflow_examples'\n",
      "\n",
      "During handling of the above exception, another exception occurred:\n",
      "\n",
      "Traceback (most recent call last):\n",
      "  File \"c:\\users\\mcsch\\anaconda3\\envs\\tf20\\lib\\site-packages\\IPython\\core\\interactiveshell.py\", line 2044, in showtraceback\n",
      "    stb = value._render_traceback_()\n",
      "AttributeError: 'ModuleNotFoundError' object has no attribute '_render_traceback_'\n",
      "\n",
      "During handling of the above exception, another exception occurred:\n",
      "\n",
      "Traceback (most recent call last):\n",
      "  File \"c:\\users\\mcsch\\anaconda3\\envs\\tf20\\lib\\site-packages\\IPython\\core\\ultratb.py\", line 1169, in get_records\n",
      "    return _fixed_getinnerframes(etb, number_of_lines_of_context, tb_offset)\n",
      "  File \"c:\\users\\mcsch\\anaconda3\\envs\\tf20\\lib\\site-packages\\IPython\\core\\ultratb.py\", line 316, in wrapped\n",
      "    return f(*args, **kwargs)\n",
      "  File \"c:\\users\\mcsch\\anaconda3\\envs\\tf20\\lib\\site-packages\\IPython\\core\\ultratb.py\", line 350, in _fixed_getinnerframes\n",
      "    records = fix_frame_records_filenames(inspect.getinnerframes(etb, context))\n",
      "  File \"c:\\users\\mcsch\\anaconda3\\envs\\tf20\\lib\\inspect.py\", line 1490, in getinnerframes\n",
      "    frameinfo = (tb.tb_frame,) + getframeinfo(tb, context)\n",
      "  File \"c:\\users\\mcsch\\anaconda3\\envs\\tf20\\lib\\inspect.py\", line 1448, in getframeinfo\n",
      "    filename = getsourcefile(frame) or getfile(frame)\n",
      "  File \"c:\\users\\mcsch\\anaconda3\\envs\\tf20\\lib\\inspect.py\", line 696, in getsourcefile\n",
      "    if getattr(getmodule(object, filename), '__loader__', None) is not None:\n",
      "  File \"c:\\users\\mcsch\\anaconda3\\envs\\tf20\\lib\\inspect.py\", line 733, in getmodule\n",
      "    if ismodule(module) and hasattr(module, '__file__'):\n",
      "  File \"c:\\users\\mcsch\\anaconda3\\envs\\tf20\\lib\\site-packages\\tensorflow\\__init__.py\", line 50, in __getattr__\n",
      "    module = self._load()\n",
      "  File \"c:\\users\\mcsch\\anaconda3\\envs\\tf20\\lib\\site-packages\\tensorflow\\__init__.py\", line 44, in _load\n",
      "    module = _importlib.import_module(self.__name__)\n",
      "  File \"c:\\users\\mcsch\\anaconda3\\envs\\tf20\\lib\\importlib\\__init__.py\", line 126, in import_module\n",
      "    return _bootstrap._gcd_import(name[level:], package, level)\n",
      "  File \"<frozen importlib._bootstrap>\", line 994, in _gcd_import\n",
      "  File \"<frozen importlib._bootstrap>\", line 971, in _find_and_load\n",
      "  File \"<frozen importlib._bootstrap>\", line 953, in _find_and_load_unlocked\n",
      "ModuleNotFoundError: No module named 'tensorflow_core.estimator'\n",
      "Traceback (most recent call last):\n",
      "  File \"c:\\users\\mcsch\\anaconda3\\envs\\tf20\\lib\\site-packages\\IPython\\core\\interactiveshell.py\", line 3343, in run_code\n",
      "    exec(code_obj, self.user_global_ns, self.user_ns)\n",
      "  File \"<ipython-input-1-f8a46eff5ac0>\", line 3, in <module>\n",
      "    from tensorflow_examples.models.pix2pix import pix2pix\n",
      "ModuleNotFoundError: No module named 'tensorflow_examples'\n",
      "\n",
      "During handling of the above exception, another exception occurred:\n",
      "\n",
      "Traceback (most recent call last):\n",
      "  File \"c:\\users\\mcsch\\anaconda3\\envs\\tf20\\lib\\site-packages\\IPython\\core\\interactiveshell.py\", line 2044, in showtraceback\n",
      "    stb = value._render_traceback_()\n",
      "AttributeError: 'ModuleNotFoundError' object has no attribute '_render_traceback_'\n",
      "\n",
      "During handling of the above exception, another exception occurred:\n",
      "\n",
      "Traceback (most recent call last):\n",
      "  File \"c:\\users\\mcsch\\anaconda3\\envs\\tf20\\lib\\site-packages\\IPython\\core\\interactiveshell.py\", line 3263, in run_ast_nodes\n",
      "    if (await self.run_code(code, result,  async_=asy)):\n",
      "  File \"c:\\users\\mcsch\\anaconda3\\envs\\tf20\\lib\\site-packages\\IPython\\core\\interactiveshell.py\", line 3360, in run_code\n",
      "    self.showtraceback(running_compiled_code=True)\n",
      "  File \"c:\\users\\mcsch\\anaconda3\\envs\\tf20\\lib\\site-packages\\IPython\\core\\interactiveshell.py\", line 2047, in showtraceback\n",
      "    value, tb, tb_offset=tb_offset)\n",
      "  File \"c:\\users\\mcsch\\anaconda3\\envs\\tf20\\lib\\site-packages\\IPython\\core\\ultratb.py\", line 1436, in structured_traceback\n",
      "    self, etype, value, tb, tb_offset, number_of_lines_of_context)\n",
      "  File \"c:\\users\\mcsch\\anaconda3\\envs\\tf20\\lib\\site-packages\\IPython\\core\\ultratb.py\", line 1336, in structured_traceback\n",
      "    self, etype, value, tb, tb_offset, number_of_lines_of_context\n",
      "  File \"c:\\users\\mcsch\\anaconda3\\envs\\tf20\\lib\\site-packages\\IPython\\core\\ultratb.py\", line 1193, in structured_traceback\n",
      "    tb_offset)\n",
      "  File \"c:\\users\\mcsch\\anaconda3\\envs\\tf20\\lib\\site-packages\\IPython\\core\\ultratb.py\", line 1150, in format_exception_as_a_whole\n",
      "    last_unique, recursion_repeat = find_recursion(orig_etype, evalue, records)\n",
      "  File \"c:\\users\\mcsch\\anaconda3\\envs\\tf20\\lib\\site-packages\\IPython\\core\\ultratb.py\", line 451, in find_recursion\n",
      "    return len(records), 0\n",
      "TypeError: object of type 'NoneType' has no len()\n",
      "\n",
      "During handling of the above exception, another exception occurred:\n",
      "\n",
      "Traceback (most recent call last):\n",
      "  File \"c:\\users\\mcsch\\anaconda3\\envs\\tf20\\lib\\site-packages\\IPython\\core\\interactiveshell.py\", line 2044, in showtraceback\n",
      "    stb = value._render_traceback_()\n",
      "AttributeError: 'TypeError' object has no attribute '_render_traceback_'\n",
      "\n",
      "During handling of the above exception, another exception occurred:\n",
      "\n",
      "Traceback (most recent call last):\n",
      "  File \"c:\\users\\mcsch\\anaconda3\\envs\\tf20\\lib\\site-packages\\IPython\\core\\ultratb.py\", line 1169, in get_records\n",
      "    return _fixed_getinnerframes(etb, number_of_lines_of_context, tb_offset)\n",
      "  File \"c:\\users\\mcsch\\anaconda3\\envs\\tf20\\lib\\site-packages\\IPython\\core\\ultratb.py\", line 316, in wrapped\n",
      "    return f(*args, **kwargs)\n",
      "  File \"c:\\users\\mcsch\\anaconda3\\envs\\tf20\\lib\\site-packages\\IPython\\core\\ultratb.py\", line 350, in _fixed_getinnerframes\n",
      "    records = fix_frame_records_filenames(inspect.getinnerframes(etb, context))\n",
      "  File \"c:\\users\\mcsch\\anaconda3\\envs\\tf20\\lib\\inspect.py\", line 1490, in getinnerframes\n",
      "    frameinfo = (tb.tb_frame,) + getframeinfo(tb, context)\n",
      "  File \"c:\\users\\mcsch\\anaconda3\\envs\\tf20\\lib\\inspect.py\", line 1448, in getframeinfo\n",
      "    filename = getsourcefile(frame) or getfile(frame)\n",
      "  File \"c:\\users\\mcsch\\anaconda3\\envs\\tf20\\lib\\inspect.py\", line 696, in getsourcefile\n",
      "    if getattr(getmodule(object, filename), '__loader__', None) is not None:\n",
      "  File \"c:\\users\\mcsch\\anaconda3\\envs\\tf20\\lib\\inspect.py\", line 733, in getmodule\n",
      "    if ismodule(module) and hasattr(module, '__file__'):\n",
      "  File \"c:\\users\\mcsch\\anaconda3\\envs\\tf20\\lib\\site-packages\\tensorflow\\__init__.py\", line 50, in __getattr__\n",
      "    module = self._load()\n",
      "  File \"c:\\users\\mcsch\\anaconda3\\envs\\tf20\\lib\\site-packages\\tensorflow\\__init__.py\", line 44, in _load\n",
      "    module = _importlib.import_module(self.__name__)\n",
      "  File \"c:\\users\\mcsch\\anaconda3\\envs\\tf20\\lib\\importlib\\__init__.py\", line 126, in import_module\n",
      "    return _bootstrap._gcd_import(name[level:], package, level)\n",
      "  File \"<frozen importlib._bootstrap>\", line 994, in _gcd_import\n",
      "  File \"<frozen importlib._bootstrap>\", line 971, in _find_and_load\n",
      "  File \"<frozen importlib._bootstrap>\", line 953, in _find_and_load_unlocked\n",
      "ModuleNotFoundError: No module named 'tensorflow_core.estimator'\n",
      "Traceback (most recent call last):\n",
      "  File \"c:\\users\\mcsch\\anaconda3\\envs\\tf20\\lib\\site-packages\\IPython\\core\\interactiveshell.py\", line 3343, in run_code\n",
      "    exec(code_obj, self.user_global_ns, self.user_ns)\n",
      "  File \"<ipython-input-1-f8a46eff5ac0>\", line 3, in <module>\n",
      "    from tensorflow_examples.models.pix2pix import pix2pix\n",
      "ModuleNotFoundError: No module named 'tensorflow_examples'\n",
      "\n",
      "During handling of the above exception, another exception occurred:\n",
      "\n",
      "Traceback (most recent call last):\n",
      "  File \"c:\\users\\mcsch\\anaconda3\\envs\\tf20\\lib\\site-packages\\IPython\\core\\interactiveshell.py\", line 2044, in showtraceback\n",
      "    stb = value._render_traceback_()\n",
      "AttributeError: 'ModuleNotFoundError' object has no attribute '_render_traceback_'\n",
      "\n",
      "During handling of the above exception, another exception occurred:\n",
      "\n",
      "Traceback (most recent call last):\n",
      "  File \"c:\\users\\mcsch\\anaconda3\\envs\\tf20\\lib\\site-packages\\IPython\\core\\interactiveshell.py\", line 3263, in run_ast_nodes\n",
      "    if (await self.run_code(code, result,  async_=asy)):\n",
      "  File \"c:\\users\\mcsch\\anaconda3\\envs\\tf20\\lib\\site-packages\\IPython\\core\\interactiveshell.py\", line 3360, in run_code\n",
      "    self.showtraceback(running_compiled_code=True)\n",
      "  File \"c:\\users\\mcsch\\anaconda3\\envs\\tf20\\lib\\site-packages\\IPython\\core\\interactiveshell.py\", line 2047, in showtraceback\n",
      "    value, tb, tb_offset=tb_offset)\n",
      "  File \"c:\\users\\mcsch\\anaconda3\\envs\\tf20\\lib\\site-packages\\IPython\\core\\ultratb.py\", line 1436, in structured_traceback\n",
      "    self, etype, value, tb, tb_offset, number_of_lines_of_context)\n",
      "  File \"c:\\users\\mcsch\\anaconda3\\envs\\tf20\\lib\\site-packages\\IPython\\core\\ultratb.py\", line 1336, in structured_traceback\n",
      "    self, etype, value, tb, tb_offset, number_of_lines_of_context\n",
      "  File \"c:\\users\\mcsch\\anaconda3\\envs\\tf20\\lib\\site-packages\\IPython\\core\\ultratb.py\", line 1193, in structured_traceback\n",
      "    tb_offset)\n",
      "  File \"c:\\users\\mcsch\\anaconda3\\envs\\tf20\\lib\\site-packages\\IPython\\core\\ultratb.py\", line 1150, in format_exception_as_a_whole\n",
      "    last_unique, recursion_repeat = find_recursion(orig_etype, evalue, records)\n",
      "  File \"c:\\users\\mcsch\\anaconda3\\envs\\tf20\\lib\\site-packages\\IPython\\core\\ultratb.py\", line 451, in find_recursion\n",
      "    return len(records), 0\n",
      "TypeError: object of type 'NoneType' has no len()\n",
      "\n",
      "During handling of the above exception, another exception occurred:\n",
      "\n",
      "Traceback (most recent call last):\n",
      "  File \"c:\\users\\mcsch\\anaconda3\\envs\\tf20\\lib\\site-packages\\IPython\\core\\interactiveshell.py\", line 2044, in showtraceback\n",
      "    stb = value._render_traceback_()\n",
      "AttributeError: 'TypeError' object has no attribute '_render_traceback_'\n",
      "\n",
      "During handling of the above exception, another exception occurred:\n",
      "\n",
      "Traceback (most recent call last):\n",
      "  File \"c:\\users\\mcsch\\anaconda3\\envs\\tf20\\lib\\site-packages\\IPython\\core\\interactiveshell.py\", line 2895, in _run_cell\n",
      "    return runner(coro)\n",
      "  File \"c:\\users\\mcsch\\anaconda3\\envs\\tf20\\lib\\site-packages\\IPython\\core\\async_helpers.py\", line 68, in _pseudo_sync_runner\n",
      "    coro.send(None)\n",
      "  File \"c:\\users\\mcsch\\anaconda3\\envs\\tf20\\lib\\site-packages\\IPython\\core\\interactiveshell.py\", line 3072, in run_cell_async\n",
      "    interactivity=interactivity, compiler=compiler, result=result)\n",
      "  File \"c:\\users\\mcsch\\anaconda3\\envs\\tf20\\lib\\site-packages\\IPython\\core\\interactiveshell.py\", line 3282, in run_ast_nodes\n",
      "    self.showtraceback()\n",
      "  File \"c:\\users\\mcsch\\anaconda3\\envs\\tf20\\lib\\site-packages\\IPython\\core\\interactiveshell.py\", line 2047, in showtraceback\n",
      "    value, tb, tb_offset=tb_offset)\n",
      "  File \"c:\\users\\mcsch\\anaconda3\\envs\\tf20\\lib\\site-packages\\IPython\\core\\ultratb.py\", line 1436, in structured_traceback\n",
      "    self, etype, value, tb, tb_offset, number_of_lines_of_context)\n",
      "  File \"c:\\users\\mcsch\\anaconda3\\envs\\tf20\\lib\\site-packages\\IPython\\core\\ultratb.py\", line 1336, in structured_traceback\n",
      "    self, etype, value, tb, tb_offset, number_of_lines_of_context\n",
      "  File \"c:\\users\\mcsch\\anaconda3\\envs\\tf20\\lib\\site-packages\\IPython\\core\\ultratb.py\", line 1211, in structured_traceback\n",
      "    chained_exceptions_tb_offset)\n",
      "  File \"c:\\users\\mcsch\\anaconda3\\envs\\tf20\\lib\\site-packages\\IPython\\core\\ultratb.py\", line 1150, in format_exception_as_a_whole\n",
      "    last_unique, recursion_repeat = find_recursion(orig_etype, evalue, records)\n",
      "  File \"c:\\users\\mcsch\\anaconda3\\envs\\tf20\\lib\\site-packages\\IPython\\core\\ultratb.py\", line 451, in find_recursion\n",
      "    return len(records), 0\n",
      "TypeError: object of type 'NoneType' has no len()\n",
      "\n",
      "During handling of the above exception, another exception occurred:\n",
      "\n",
      "Traceback (most recent call last):\n",
      "  File \"c:\\users\\mcsch\\anaconda3\\envs\\tf20\\lib\\site-packages\\IPython\\core\\interactiveshell.py\", line 2044, in showtraceback\n",
      "    stb = value._render_traceback_()\n",
      "AttributeError: 'TypeError' object has no attribute '_render_traceback_'\n",
      "\n",
      "During handling of the above exception, another exception occurred:\n",
      "\n",
      "Traceback (most recent call last):\n",
      "  File \"c:\\users\\mcsch\\anaconda3\\envs\\tf20\\lib\\site-packages\\IPython\\core\\ultratb.py\", line 1169, in get_records\n",
      "    return _fixed_getinnerframes(etb, number_of_lines_of_context, tb_offset)\n",
      "  File \"c:\\users\\mcsch\\anaconda3\\envs\\tf20\\lib\\site-packages\\IPython\\core\\ultratb.py\", line 316, in wrapped\n",
      "    return f(*args, **kwargs)\n",
      "  File \"c:\\users\\mcsch\\anaconda3\\envs\\tf20\\lib\\site-packages\\IPython\\core\\ultratb.py\", line 350, in _fixed_getinnerframes\n",
      "    records = fix_frame_records_filenames(inspect.getinnerframes(etb, context))\n",
      "  File \"c:\\users\\mcsch\\anaconda3\\envs\\tf20\\lib\\inspect.py\", line 1490, in getinnerframes\n",
      "    frameinfo = (tb.tb_frame,) + getframeinfo(tb, context)\n",
      "  File \"c:\\users\\mcsch\\anaconda3\\envs\\tf20\\lib\\inspect.py\", line 1448, in getframeinfo\n",
      "    filename = getsourcefile(frame) or getfile(frame)\n",
      "  File \"c:\\users\\mcsch\\anaconda3\\envs\\tf20\\lib\\inspect.py\", line 696, in getsourcefile\n",
      "    if getattr(getmodule(object, filename), '__loader__', None) is not None:\n",
      "  File \"c:\\users\\mcsch\\anaconda3\\envs\\tf20\\lib\\inspect.py\", line 733, in getmodule\n",
      "    if ismodule(module) and hasattr(module, '__file__'):\n",
      "  File \"c:\\users\\mcsch\\anaconda3\\envs\\tf20\\lib\\site-packages\\tensorflow\\__init__.py\", line 50, in __getattr__\n",
      "    module = self._load()\n",
      "  File \"c:\\users\\mcsch\\anaconda3\\envs\\tf20\\lib\\site-packages\\tensorflow\\__init__.py\", line 44, in _load\n",
      "    module = _importlib.import_module(self.__name__)\n",
      "  File \"c:\\users\\mcsch\\anaconda3\\envs\\tf20\\lib\\importlib\\__init__.py\", line 126, in import_module\n",
      "    return _bootstrap._gcd_import(name[level:], package, level)\n",
      "  File \"<frozen importlib._bootstrap>\", line 994, in _gcd_import\n",
      "  File \"<frozen importlib._bootstrap>\", line 971, in _find_and_load\n",
      "  File \"<frozen importlib._bootstrap>\", line 953, in _find_and_load_unlocked\n",
      "ModuleNotFoundError: No module named 'tensorflow_core.estimator'\n"
     ]
    }
   ],
   "source": [
    "import tensorflow as tf\n",
    "\n",
    "from tensorflow_examples.models.pix2pix import pix2pix\n",
    "\n",
    "import tensorflow_datasets as tfds\n",
    "\n",
    "from IPython.display import clear_output\n",
    "import matplotlib.pyplot as plt"
   ]
  },
  {
   "cell_type": "code",
   "execution_count": null,
   "metadata": {},
   "outputs": [],
   "source": []
  }
 ],
 "metadata": {
  "kernelspec": {
   "display_name": "Python 3",
   "language": "python",
   "name": "python3"
  },
  "language_info": {
   "codemirror_mode": {
    "name": "ipython",
    "version": 3
   },
   "file_extension": ".py",
   "mimetype": "text/x-python",
   "name": "python",
   "nbconvert_exporter": "python",
   "pygments_lexer": "ipython3",
   "version": "3.8.3"
  }
 },
 "nbformat": 4,
 "nbformat_minor": 4
}
